Workbook

Sheet 1.matematika
A1: Jadwal Kuliah Semester Gasal 2024/2025
A2: SKPB - ITS | L2: SKPB, 28 Agustus 2024
A4: Kode MK | B4: Mata Kuliah | C4: SKS | D4: Sem | E4: Kel | F4: Nama Kelas SIAKAD | G4: Jumlah Mhs SIAKAD | H4: Departemen | I4: Hari / Pukul | J4: Ruang | K4: Lokasi Ruang | L4: Dosen Pembina | M4: Pertemuan | N4: SKS | O4: Asisten | P4: Link WA Asisten
A5: SM234101 | B5: Kalkulus 1 | C5: 3 | D5: 1 | E5: Kal-1 | F5: 5 | G5: 78 | H5: T. Sipil, T. Lingkungan, T. Geomatika, T. Geofisika, Tekdok | I5: Selasa, Kamis; 07.00-08.40 | J5: TW1-502 | K5: Tower 1, lt. 5 | L5: Drs. Suhud Wahyudi, M.Si. | O5: Michael Putra Nababan | P5: =VLOOKUP(O5,Sheet1!$B$3:$D$55,3,FALSE) -> KLIK UNTUK CHAT
A6: SM234101 | B6: Kalkulus 1 | C6: 3 | D6: 1 | F6: 6 | G6: 78 | H6: T. Sipil, T. Lingkungan, T. Geomatika, T. Geofisika, Tekdok | I6: Selasa, Kamis; 07.00-08.40 | J6: TW1-503 | K6: Tower 1, lt. 5 | L6: Dr. Dieky Adzkiya, S.Si, M.Si / Mohamad Ilham Dwi Firmansyah, M. Mat. | M6: 16/16 | N6: 1,5/1,5 | O6: Dimas Setyo Asmoro | P6: =VLOOKUP(O6,Sheet1!$B$3:$D$55,3,FALSE) -> KLIK UNTUK CHAT
A7: SM234101 | B7: Kalkulus 1 | C7: 3 | D7: 1 | F7: 7 | G7: 78 | H7: T. Sipil, T. Lingkungan, T. Geomatika, T. Geofisika, Tekdok | I7: Selasa, Kamis; 07.00-08.40 | J7: TW1-505 | K7: Tower 1, lt. 5 | L7: Ainun Kusnul Khotimah, M. Mat. / Prof. Dr. Dra. Mardlijah, M.T | M7: 22/10 | N7: 2/1 | O7: Mahendra Darmadiyaksa Fatah Hariyadi | P7: =VLOOKUP(O7,Sheet1!$B$3:$D$55,3,FALSE) -> KLIK UNTUK CHAT
A8: SM234101 | B8: Kalkulus 1 | C8: 3 | D8: 1 | F8: 8 | G8: 78 | H8: T. Sipil, T. Lingkungan, T. Geomatika, T. Geofisika, Tekdok | I8: Selasa, Kamis; 07.00-08.40 | J8: TW1-601 | K8: Tower 1, lt. 6 | L8: Drs. Sadjidon, M.Si | O8: Miftahul Huda | P8: =VLOOKUP(O8,Sheet1!$B$3:$D$55,3,FALSE) -> KLIK UNTUK CHAT
A9: SM234101 | B9: Kalkulus 1 | C9: 3 | D9: 1 | F9: 9 | G9: 78 | H9: T. Sipil, T. Lingkungan, T. Geomatika, T. Geofisika, Tekdok | I9: Selasa, Kamis; 07.00-08.40 | J9: TW1-602 | K9: Tower 1, lt. 6 | L9: Dr. Dieky Adzkiya, S.Si, M.Si / Mohamad Ilham Dwi Firmansyah, M. Mat. | M9: 16/16 | N9: 1,5/1,5 | O9: Sang Nyoman Agastya Mahesa Pranatha Kaler | P9: =VLOOKUP(O9,Sheet1!$B$3:$D$55,3,FALSE) -> KLIK UNTUK CHAT
A10: SM234101 | B10: Kalkulus 1 | C10: 3 | D10: 1 | F10: 10 | G10: 78 | H10: T. Sipil, T. Lingkungan, T. Geomatika, T. Geofisika, Tekdok | I10: Selasa, Kamis; 07.00-08.40 | J10: TW1-603 | K10: Tower 1, lt. 6 | L10: Alvian Alif Hidayatullah, M. Mat./ Sena Safarina, S.Si, M.Sc, D.Sc | M10: 22/10 | N10: 2/1 | O10: Najwa Azalia Zakhia Musthofa | P10: =VLOOKUP(O10,Sheet1!$B$3:$D$55,3,FALSE) -> KLIK UNTUK CHAT
A11: SM234101 | B11: Kalkulus 1 | C11: 3 | D11: 1 | F11: 11 | G11: 78 | H11: T. Sipil, T. Lingkungan, T. Geomatika, T. Geofisika, Tekdok | I11: Selasa, Kamis; 07.00-08.40 | J11: TW1-605 | K11: Tower 1, lt. 6 | L11: Raden Aurelius Andhika Viadinugroho, S.Si., M.Sc. / Dr. Darmaji,S.Si., MT. | M11: 16/16 | N11: 1,5/1,5 | O11: Muhammad Satria Rahman | P11: =VLOOKUP(O11,Sheet1!$B$3:$D$55,3,FALSE) -> KLIK UNTUK CHAT
A12: SM234101 | B12: Kalkulus 1 | C12: 3 | D12: 1 | F12: 12 | G12: 78 | H12: T. Sipil, T. Lingkungan, T. Geomatika, T. Geofisika, Tekdok | I12: Selasa, Kamis; 07.00-08.40 | J12: TW1-701 | K12: Tower 1, lt. 7 | L12: Dr. Tahiyatul Asfihani / Dra. Wahyu Fistia Doctorina, M.Si / Ridho Nur Rohman Wijaya, S.Mat., M. Mat. | M12: 5/16/11 | N12: 0,5/1,5/1 | O12: Aufa Al Musyarof | P12: =VLOOKUP(O12,Sheet1!$B$3:$D$55,3,FALSE) -> KLIK UNTUK CHAT
A13: SM234101 | B13: Kalkulus 1 | C13: 3 | D13: ≥3 | F13: 101 | G13: 62 | H13: T. Sipil, T. Lingkungan, T. Geomatika, T. Geofisika, Tekdok | I13: Selasa, Kamis; 07.00-08.40 | J13: TW1-705 | K13: Tower 1, lt. 7 | L13: Raden Aurelius Andhika Viadinugroho, S.Si., M.Sc / Dr. Darmaji,S.Si., MT. | M13: 16/16 | N13: 1,5/1,5 | O13: Farhan Rif'at Mauludani | P13: =VLOOKUP(O13,Sheet1!$B$3:$D$55,3,FALSE) -> KLIK UNTUK CHAT
A14: SM234101 | B14: Kalkulus 1 | C14: 3 | D14: 1 | E14: Kal-2 | F14: 13 | G14: 77 | H14: T. Perkapalan, T. Sistem Perkapalan, T. Kelautan, T. Transportasi Laut, T. Bangunan Lepas Pantai | I14: Senin, Rabu; 07.00-08.40 | J14: TW1-201 | K14: Tower 1, lt. 2 | L14: Drs. Sentot Didik Surjanto, M.Si / Muhammad Yusuf Hakim Widianto, S.Si., M.Si., M.Sc., Ph.D. | M14: 16/16 | N14: 1,5/1,5 | O14: Farhan Rif'at Mauludani | P14: =VLOOKUP(O14,Sheet1!$B$3:$D$55,3,FALSE) -> KLIK UNTUK CHAT
A15: SM234101 | B15: Kalkulus 1 | C15: 3 | D15: 1 | F15: 14 | G15: 77 | H15: T. Perkapalan, T. Sistem Perkapalan, T. Kelautan, T. Transportasi Laut, T. Bangunan Lepas Pantai | I15: Senin, Rabu; 07.00-08.40 | J15: TW1-202 | K15: Tower 1, lt. 2 | L15: Amirul Hakam, S.Si., M.Si. / Dra. Laksmi Prita Wardani, M.Si. | M15: 16/16 | N15: 1,5/1,5 | O15: Muhammad Shafa Narariya | P15: =VLOOKUP(O15,Sheet1!$B$3:$D$55,3,FALSE) -> KLIK UNTUK CHAT
A16: SM234101 | B16: Kalkulus 1 | C16: 3 | D16: 1 | F16: 15 | G16: 77 | H16: T. Perkapalan, T. Sistem Perkapalan, T. Kelautan, T. Transportasi Laut, T. Bangunan Lepas Pantai | I16: Senin, Rabu; 07.00-08.40 | J16: TW1-203 | K16: Tower 1, lt. 2 | L16: Dr. Dwi Ratna /Mohamad Ilham Dwi Firmansyah, M. Mat. | M16: 10/22 | N16: 1/2 | O16: Rizky Alviando | P16: =VLOOKUP(O16,Sheet1!$B$3:$D$55,3,FALSE) -> KLIK UNTUK CHAT
A17: SM234101 | B17: Kalkulus 1 | C17: 3 | D17: 1 | F17: 16 | G17: 77 | H17: T. Perkapalan, T. Sistem Perkapalan, T. Kelautan, T. Transportasi Laut, T. Bangunan Lepas Pantai | I17: Senin, Rabu; 07.00-08.40 | J17: TW1-205 | K17: Tower 1, lt. 2 | L17: Dra. Nur Asiyah, M.Si | O17: Vishnu Krishna Darojati | P17: =VLOOKUP(O17,Sheet1!$B$3:$D$55,3,FALSE) -> KLIK UNTUK CHAT
A18: SM234101 | B18: Kalkulus 1 | C18: 3 | D18: 1 | F18: 17 | G18: 77 | H18: T. Perkapalan, T. Sistem Perkapalan, T. Kelautan, T. Transportasi Laut, T. Bangunan Lepas Pantai | I18: Senin, Rabu; 07.00-08.40 | J18: TW1-206 | K18: Tower 1, lt. 2 | L18: Amirul Hakam, S.Si., M.Si. / Dra. Laksmi Prita Wardani, M.Si. | M18: 16/16 | N18: 1,5/1,5 | O18: Haritsa Dhiya Ulhaq | P18: =VLOOKUP(O18,Sheet1!$B$3:$D$55,3,FALSE) -> KLIK UNTUK CHAT
A19: SM234101 | B19: Kalkulus 1 | C19: 3 | D19: 1 | F19: 18 | G19: 77 | H19: T. Perkapalan, T. Sistem Perkapalan, T. Kelautan, T. Transportasi Laut, T. Bangunan Lepas Pantai | I19: Senin, Rabu; 07.00-08.40 | J19: TW1-301 | K19: Tower 1, lt. 3 | L19: Drs. Sentot Didik Surjanto, M.Si / Muhammad Yusuf Hakim Widianto, S.Si., M.Si., M.Sc., Ph.D. | M19: 16/16 | N19: 1,5/1,5 | O19: Aditya Wahyudinanta | P19: =VLOOKUP(O19,Sheet1!$B$3:$D$55,3,FALSE) -> KLIK UNTUK CHAT
A20: SM234101 | B20: Kalkulus 1 | C20: 3 | D20: 1 | F20: 19 | G20: 77 | H20: T. Perkapalan, T. Sistem Perkapalan, T. Kelautan, T. Transportasi Laut, T. Bangunan Lepas Pantai | I20: Senin, Rabu; 07.00-08.40 | J20: TW1-302 | K20: Tower 1, lt. 3 | L20: Drs. I.G.Ngurah Rai Usada, M.Si / Dr. Tahiyatul Asfihani, S.Si, M.Si | M20: 27/5 | N20: 2,5/0,5 | O20: Nadya Eka Sri Wulandari | P20: =VLOOKUP(O20,Sheet1!$B$3:$D$55,3,FALSE) -> KLIK UNTUK CHAT
A21: SM234101 | B21: Kalkulus 1 | C21: 3 | D21: ≥3 | F21: 103 | G21: 57 | H21: T. Perkapalan, T. Sistem Perkapalan, T. Kelautan, T. Transportasi Laut, T. Bangunan Lepas Pantai | I21: Senin, Rabu; 07.00-08.40 | J21: TW1-803 | K21: Tower 1, lt. 8 | L21: Ridho Nur Rohman Wijaya, S.Mat., M. Mat. / Drs. Suhud Wahyudi, M.Si. | M21: 22/10 | N21: 2/1 | O21: Dzaky Muhammad | P21: =VLOOKUP(O21,Sheet1!$B$3:$D$55,3,FALSE) -> KLIK UNTUK CHAT
A22: SM234101 | B22: Kalkulus 1 | C22: 3 | D22: 1 | E22: Kal-3 | F22: 20 | G22: 78 | H22: T. Mesin, T. Kimia, T. Fisika, Teknik Sistem dan Industri, T. Material dan Metalurgi, T. Pangan, Rkp | I22: Selasa, Kamis; 11.00-12.40 | J22: TW1-301 | K22: Tower 1, lt. 3 | L22: Drs. Komar Baihaqi, M.Si / Ainun Kusnul Khotimah, M. Mat. | M22: 16/16 | N22: 1,5/1,5 | O22: Aulia Aisyah Harhary | P22: =VLOOKUP(O22,Sheet1!$B$3:$D$55,3,FALSE) -> KLIK UNTUK CHAT
A23: SM234101 | B23: Kalkulus 1 | C23: 3 | D23: 1 | F23: 21 | G23: 78 | H23: T. Mesin, T. Kimia, T. Fisika, Teknik Sistem dan Industri, T. Material dan Metalurgi, T. Pangan, Rkp | I23: Selasa, Kamis; 11.00-12.40 | J23: TW1-302 | K23: Tower 1, lt. 3 | L23: Drs. Iis Herisman, M.Sc. | O23: Junika Irdia Indi Astudin | P23: =VLOOKUP(O23,Sheet1!$B$3:$D$55,3,FALSE) -> KLIK UNTUK CHAT
A24: SM234101 | B24: Kalkulus 1 | C24: 3 | D24: 1 | F24: 22 | G24: 78 | H24: T. Mesin, T. Kimia, T. Fisika, Teknik Sistem dan Industri, T. Material dan Metalurgi, T. Pangan, Rkp | I24: Selasa, Kamis; 11.00-12.40 | J24: TW1-303 | K24: Tower 1, lt. 3 | L24: Prof. Dr. Drs. Chairul Imron, MI.Komp. | O24: Triwanto | P24: =VLOOKUP(O24,Sheet1!$B$3:$D$55,3,FALSE) -> KLIK UNTUK CHAT
A25: SM234101 | B25: Kalkulus 1 | C25: 3 | D25: 1 | F25: 23 | G25: 78 | H25: T. Mesin, T. Kimia, T. Fisika, Teknik Sistem dan Industri, T. Material dan Metalurgi, T. Pangan, Rkp | I25: Selasa, Kamis; 11.00-12.40 | J25: TW1-305 | K25: Tower 1, lt. 3 | L25: Dra. Laksmi Prita Wardani, M.Si. | O25: Mu'iza Kaba Latif | P25: =VLOOKUP(O25,Sheet1!$B$3:$D$55,3,FALSE) -> KLIK UNTUK CHAT
A26: SM234101 | B26: Kalkulus 1 | C26: 3 | D26: 1 | F26: 24 | G26: 78 | H26: T. Mesin, T. Kimia, T. Fisika, Teknik Sistem dan Industri, T. Material dan Metalurgi, T. Pangan, Rkp | I26: Selasa, Kamis; 11.00-12.40 | J26: TW1-306 | K26: Tower 1, lt. 3 | L26: Drs. Suhud Wahyudi, M.Si. | O26: Aditya Wahyudinanta | P26: =VLOOKUP(O26,Sheet1!$B$3:$D$55,3,FALSE) -> KLIK UNTUK CHAT
A27: SM234101 | B27: Kalkulus 1 | C27: 3 | D27: 1 | F27: 25 | G27: 78 | H27: T. Mesin, T. Kimia, T. Fisika, Teknik Sistem dan Industri, T. Material dan Metalurgi, T. Pangan, Rkp | I27: Selasa, Kamis; 11.00-12.40 | J27: TW1-501 | K27: Tower 1, lt. 5 | L27: Alvida Mustika Rukmi, S.Si, M.Si / Raden Aurelius Andhika Viadinugroho, S.Si., M.Sc. | M27: 16/16 | N27: 1,5/1,5 | O27: Nur Millatul Af Idah | P27: =VLOOKUP(O27,Sheet1!$B$3:$D$55,3,FALSE) -> KLIK UNTUK CHAT
A28: SM234101 | B28: Kalkulus 1 | C28: 3 | D28: 1 | F28: 26 | G28: 78 | H28: T. Mesin, T. Kimia, T. Fisika, Teknik Sistem dan Industri, T. Material dan Metalurgi, T. Pangan, Rkp | I28: Selasa, Kamis; 11.00-12.40 | J28: TW1-502 | K28: Tower 1, lt. 5 | L28: Drs. Sadjidon, M.Si | O28: Maulida Rahmi | P28: =VLOOKUP(O28,Sheet1!$B$3:$D$55,3,FALSE) -> KLIK UNTUK CHAT
A29: SM234101 | B29: Kalkulus 1 | C29: 3 | D29: 1 | F29: 27 | G29: 77 | H29: T. Mesin, T. Kimia, T. Fisika, Teknik Sistem dan Industri, T. Material dan Metalurgi, T. Pangan, Rkp | I29: Selasa, Kamis; 11.00-12.40 | J29: TW1-503 | K29: Tower 1, lt. 5 | L29: Prof. Dr.techn. Drs. Mohammad Isa Irawan, M.T | O29: Satrio Wicaksono Viernadi | P29: =VLOOKUP(O29,Sheet1!$B$3:$D$55,3,FALSE) -> KLIK UNTUK CHAT
A30: SM234101 | B30: Kalkulus 1 | C30: 3 | D30: 1 | F30: 28 | G30: 77 | H30: T. Mesin, T. Kimia, T. Fisika, Teknik Sistem dan Industri, T. Material dan Metalurgi, T. Pangan, Rkp | I30: Selasa, Kamis; 11.00-12.40 | J30: TW1-505 | K30: Tower 1, lt. 5 | L30: Dian Winda Setyawati,S.Si, M.Si | O30: Ahmad Hisbu Zakiyudin | P30: =VLOOKUP(O30,Sheet1!$B$3:$D$55,3,FALSE) -> KLIK UNTUK CHAT
A31: SM234101 | B31: Kalkulus 1 | C31: 3 | D31: 1 | F31: 29 | G31: 77 | H31: T. Mesin, T. Kimia, T. Fisika, Teknik Sistem dan Industri, T. Material dan Metalurgi, T. Pangan, Rkp | I31: Selasa, Kamis; 11.00-12.40 | J31: TW1-601 | K31: Tower 1, lt. 6 | L31: Drs. Sentot Didik Surjanto, M.Si | O31: Winda Nafiqih Irawan | P31: =VLOOKUP(O31,Sheet1!$B$3:$D$55,3,FALSE) -> KLIK UNTUK CHAT
A32: SM234101 | B32: Kalkulus 1 | C32: 3 | D32: 1 | F32: 30 | G32: 77 | H32: T. Mesin, T. Kimia, T. Fisika, Teknik Sistem dan Industri, T. Material dan Metalurgi, T. Pangan, Rkp | I32: Selasa, Kamis; 11.00-12.40 | J32: TW1-602 | K32: Tower 1, lt. 6 | L32: Dr. Drs. Mahmud Yunus, M.Si / Mohamad Ilham Dwi Firmansyah, M. Mat. | M32: 10/22 | N32: 1/2 | O32: Dzaky Muhammad | P32: =VLOOKUP(O32,Sheet1!$B$3:$D$55,3,FALSE) -> KLIK UNTUK CHAT
A33: SM234101 | B33: Kalkulus 1 | C33: 3 | D33: 1 | F33: 31 | G33: 77 | H33: T. Mesin, T. Kimia, T. Fisika, Teknik Sistem dan Industri, T. Material dan Metalurgi, T. Pangan, Rkp | I33: Selasa, Kamis; 11.00-12.40 | J33: TW1-603 | K33: Tower 1, lt. 6 | L33: Ridho Nur Rohman Wijaya, S.Mat., M. Mat. / Dr. Budi Setiyono, S.Si, MT | M33: 22/10 | N33: 2/1 | O33: Sharfina Ardhiyanti Anam | P33: =VLOOKUP(O33,Sheet1!$B$3:$D$55,3,FALSE) -> KLIK UNTUK CHAT
A34: SM234101 | B34: Kalkulus 1 | C34: 3 | D34: 1 | F34: 32 | G34: 77 | H34: T. Mesin, T. Kimia, T. Fisika, Teknik Sistem dan Industri, T. Material dan Metalurgi, T. Pangan, Rkp | I34: Selasa, Kamis; 11.00-12.40 | J34: TW1-605 | K34: Tower 1, lt. 6 | L34: Alvian Alif Hidayatullah, M. Mat. / Prof. Subchan, S.Si, M.Sc, Ph.D | M34: 22/10 | N34: 2/1 | O34: Abdillah Dwi Cahya | P34: =VLOOKUP(O34,Sheet1!$B$3:$D$55,3,FALSE) -> KLIK UNTUK CHAT
A35: SM234101 | B35: Kalkulus 1 | C35: 3 | D35: 1 | F35: 33 | G35: 77 | H35: T. Mesin, T. Kimia, T. Fisika, Teknik Sistem dan Industri, T. Material dan Metalurgi, T. Pangan, Rkp | I35: Selasa, Kamis; 11.00-12.40 | J35: TW1-701 | K35: Tower 1, lt. 7 | L35: Drs. Lukman Hanafi, M.Sc / Raden Aurelius Andhika Viadinugroho, S.Si., M.Sc. | M35: 16/16 | N35: 1,5/1,5 | O35: Early Feodora Shauzan | P35: =VLOOKUP(O35,Sheet1!$B$3:$D$55,3,FALSE) -> KLIK UNTUK CHAT
A36: SM234101 | B36: Kalkulus 1 | C36: 3 | D36: ≥3 | F36: 105 | G36: 53 | H36: T. Mesin, T. Kimia, T. Fisika, Teknik Sistem dan Industri, T. Material dan Metalurgi, T. Pangan | I36: Selasa, Kamis; 11.00-12.40 | J36: TW1-802 | K36: Tower 1, lt. 8 | L36: Dr. Imam Mukhlash, S.Si, MT | O36: Launiawati Julia Chandra | P36: =VLOOKUP(O36,Sheet1!$B$3:$D$55,3,FALSE) -> KLIK UNTUK CHAT
A37: SM234101 | B37: Kalkulus 1 | C37: 3 | D37: ≥3 | F37: 106 | G37: 49 | H37: T. Mesin, T. Kimia, T. Fisika, Teknik Sistem dan Industri, T. Material dan Metalurgi, T. Pangan | I37: Selasa, Kamis; 11.00-12.40 | J37: TW1-803 | K37: Tower 1, lt. 8 | L37: Ainun Kusnul Khotimah, M. Mat. / Drs. Komar Baihaqi, M.Si | M37: 16/16 | N37: 1,5/1,5 | O37: Marcellius Fernando Robot | P37: =VLOOKUP(O37,Sheet1!$B$3:$D$55,3,FALSE) -> KLIK UNTUK CHAT
A38: SM234101 | B38: Kalkulus 1 | C38: 3 | D38: 1 | E38: Kal-4 | F38: 34 | G38: 77 | H38: Fisika, Matematika, Statistika, Kimia, Biologi, Aktuaria, Saik, Sdata | I38: Selasa, Kamis; 13.30-15.10 | J38: TW1-201 | K38: Tower 1, lt. 2 | L38: Prof. Dr. Basuki Widodo, M.Sc | O38: Nailus Syifa'i | P38: =VLOOKUP(O38,Sheet1!$B$3:$D$55,3,FALSE) -> KLIK UNTUK CHAT
A39: SM234101 | B39: Kalkulus 1 | C39: 3 | D39: 1 | F39: 35 | G39: 77 | H39: Fisika, Matematika, Statistika, Kimia, Biologi, Aktuaria, Saik, Sdata | I39: Selasa, Kamis; 13.30-15.10 | J39: TW1-202 | K39: Tower 1, lt. 2 | L39: Drs. Iis Herisman, M.Sc. | O39: Erwin Tri Prasetya | P39: =VLOOKUP(O39,Sheet1!$B$3:$D$55,3,FALSE) -> KLIK UNTUK CHAT
A40: SM234101 | B40: Kalkulus 1 | C40: 3 | D40: 1 | F40: 36 | G40: 76 | H40: Fisika, Matematika, Statistika, Kimia, Biologi, Aktuaria, Saik, Sdata | I40: Selasa, Kamis; 13.30-15.10 | J40: TW1-203 | K40: Tower 1, lt. 2 | L40: Dr. Dra. Rinurwati, M.Si | O40: William Alvin Lidjaja | P40: =VLOOKUP(O40,Sheet1!$B$3:$D$55,3,FALSE) -> KLIK UNTUK CHAT
A41: SM234101 | B41: Kalkulus 1 | C41: 3 | D41: 1 | F41: 37 | G41: 76 | H41: Fisika, Matematika, Statistika, Kimia, Biologi, Aktuaria, Saik, Sdata | I41: Selasa, Kamis; 13.30-15.10 | J41: TW1-205 | K41: Tower 1, lt. 2 | L41: Raden Aurelius Andhika Viadinugroho, S.Si., M.Sc. / Drs. Lukman Hanafi, M.Sc | M41: 16/16 | N41: 1,5/1,5 | O41: Andyka Nabil Putra | P41: =VLOOKUP(O41,Sheet1!$B$3:$D$55,3,FALSE) -> KLIK UNTUK CHAT
...

Sheet Sheet1
B3: Ahmad Hisbu Zakiyudin | C3: https://api.whatsapp.com/send?phone=6282257622058&text=Ahmad Hisbu Zakiyudin | D3: =HYPERLINK(C3,"KLIK UNTUK CHAT") -> KLIK UNTUK CHAT
B4: Ahmad Zaki Al Muntazhar | C4: https://api.whatsapp.com/send?phone=+6282252248992&text=Ahmad Zaki Al Muntazhar | D4: =HYPERLINK(C4,"KLIK UNTUK CHAT") -> KLIK UNTUK CHAT
B5: Junika Irdia Indi Astudin | C5: https://api.whatsapp.com/send?phone=+6287869023000&text=Junika Irdia Indi Astudin | D5: =HYPERLINK(C5,"KLIK UNTUK CHAT") -> KLIK UNTUK CHAT
B6: Nur Millatul Af Idah | C6: https://api.whatsapp.com/send?phone=+6285816644574&text=Nur Millatul Af Idah | D6: =HYPERLINK(C6,"KLIK UNTUK CHAT") -> KLIK UNTUK CHAT
B7: Miftahul Huda | C7: https://api.whatsapp.com/send?phone=+6287761095810&text=Miftahul Huda | D7: =HYPERLINK(C7,"KLIK UNTUK CHAT") -> KLIK UNTUK CHAT
B8: Abdillah Dwi Cahya | C8: https://api.whatsapp.com/send?phone=+6281216000286&text=Abdillah Dwi Cahya | D8: =HYPERLINK(C8,"KLIK UNTUK CHAT") -> KLIK UNTUK CHAT
B9: Mu'iza Kaba Latif | C9: https://api.whatsapp.com/send?phone=+6282143485360&text=Mu'iza Kaba Latif | D9: =HYPERLINK(C9,"KLIK UNTUK CHAT") -> KLIK UNTUK CHAT
B10: Najwa Fadhilah | C10: https://api.whatsapp.com/send?phone=+6282348025537&text=Najwa Fadhilah | D10: =HYPERLINK(C10,"KLIK UNTUK CHAT") -> KLIK UNTUK CHAT
B11: Triwanto | C11: https://api.whatsapp.com/send?phone=+6285728846625&text=Triwanto | D11: =HYPERLINK(C11,"KLIK UNTUK CHAT") -> KLIK UNTUK CHAT
B12: Vishnu Krishna Darojati | C12: https://api.whatsapp.com/send?phone=+6282229072197&text=Vishnu Krishna Darojati | D12: =HYPERLINK(C12,"KLIK UNTUK CHAT") -> KLIK UNTUK CHAT
B13: Aditya Wahyudinanta | C13: https://api.whatsapp.com/send?phone=+6282237235004&text=Aditya Wahyudinanta | D13: =HYPERLINK(C13,"KLIK UNTUK CHAT") -> KLIK UNTUK CHAT
B14: Ananda Teguh Imawan | C14: https://api.whatsapp.com/send?phone=+6285156764136&text=Ananda Teguh Imawan | D14: =HYPERLINK(C14,"KLIK UNTUK CHAT") -> KLIK UNTUK CHAT
... B55: Erwin Tri Prasetya | C55: https://api.whatsapp.com/send?phone=+6285648740749&text=Erwin Tri Prasetya | D55: =HYPERLINK(C55,"KLIK UNTUK CHAT") -> KLIK UNTUK CHAT
